package org.gtlcore.gtlcore.common.data.machines;

import org.gtlcore.gtlcore.common.data.GTLBlocks;
import org.gtlcore.gtlcore.common.data.GTLRecipeTypes;
import org.gtlcore.gtlcore.common.data.machines.structure.ArcaneIntegratedDeviceA;
import org.gtlcore.gtlcore.common.data.machines.structure.ArcaneIntegratedDeviceB;
import org.gtlcore.gtlcore.utils.Registries;

import com.gregtechceu.gtceu.GTCEu;
import com.gregtechceu.gtceu.api.data.RotationState;
import com.gregtechceu.gtceu.api.machine.MultiblockMachineDefinition;
import com.gregtechceu.gtceu.api.machine.multiblock.WorkableElectricMultiblockMachine;
import com.gregtechceu.gtceu.api.pattern.FactoryBlockPattern;
import com.gregtechceu.gtceu.api.pattern.Predicates;
import com.gregtechceu.gtceu.common.block.StoneBlockType;
import com.gregtechceu.gtceu.common.block.StoneTypes;
import com.gregtechceu.gtceu.common.data.GTBlocks;
import com.gregtechceu.gtceu.common.data.GTMachines;

import net.minecraft.network.chat.Component;
import net.minecraft.resources.ResourceLocation;
import net.minecraft.world.level.block.Blocks;

import static org.gtlcore.gtlcore.api.registries.GTLRegistration.REGISTRATE;

public class MagicMultiblock {

    public static void init() {}

    /// *远古之门祭坛*
    // public final static MultiblockMachineDefinition ANCIENT_ECHOES_ALTAR =
    /// REGISTRATE.multiblock("ancient_echoes_altar", WorkableElectricMultiblockMachine::new)
    // .rotationState(RotationState.NON_Y_AXIS)
    // .allowExtendedFacing(false)
    // .recipeType(GTLRecipeTypes.CALL_OF_THE_ANCIENTS)
    // .appearanceBlock(() -> Blocks.STONE_BRICKS)
    // .pattern(definition -> FactoryBlockPattern.start()
    // .aisle(" ", " AAAAAAAHHHHAAAAAAA ", " B B ", " ", " ", " ", " ", " ", " ")
    // .aisle(" AAAAAAAAHHAAAAAAAA ", " AAAAACCCCCCCCCCCCCCCCCCAAAAA ", " DADADADAHHADADADAD ", " E E E EB BE E E E ", "
    /// ", " ", " ", " ", " ")
    // .aisle(" AAAAA AAAAA ", " AAAACCCCC CCCCCAAAA ", " ADADA ADADA ", " E E E E ", " ", " ", " ", " ", " ")
    // .aisle(" AAAA AAAA ", " ACCCC CCCCA ", " ADAD DADA ", " E E E E ", " ", " ", " ", " ", " ")
    // .aisle(" A A ", " AAC CAA ", " D D ", " E E ", " ", " ", " ", " ", " ")
    // .aisle(" AA AA ", "ACC CCA", " AA AA ", " B B ", " ", " ", " ", " ", " ")
    // .aisle(" A A ", "AC FFFFFFFFFFFFFFFFFFFFFF CA", "BD F F DB", " E F F E ", " F F ", " F F ", " F F ", " F F ", "
    /// FFFFFFFFFFFFFFFFFFFFFF ")
    // .aisle(" AA AA ", "ACC CCA", " AA AA ", " B B ", " ", " ", " ", " ", " ")
    // .aisle(" A A ", " AAC CAA ", " D D ", " E E ", " ", " ", " ", " ", " ")
    // .aisle(" AAAA AAAA ", " ACCCC CCCCA ", " ADAD DADA ", " E E E E ", " ", " ", " ", " ", " ")
    // .aisle(" AAAAA AAAAA ", " AAAACCCCC CCCCCAAAA ", " ADADA ADADA ", " E E E E ", " ", " ", " ", " ", " ")
    // .aisle(" AAAAAAAAHHAAAAAAAA ", " AAAAACCCCCCCCCCCCCCCCCCAAAAA ", " DADADADAHHADADADAD ", " E E E EB BE E E E ", "
    /// ", " ", " ", " ", " ")
    // .aisle(" ", " AAAAAAAHIHHAAAAAAA ", " B B ", " ", " ", " ", " ", " ", " ")
    // .where("H", Predicates.blocks(Blocks.STONE_BRICKS)
    // .or(Predicates.autoAbilities(definition.getRecipeTypes())))
    // .where("D", Predicates.blocks(Blocks.SOUL_SAND))
    // .where("B", Predicates.blocks(Blocks.CANDLE))
    // .where("F", Predicates.blocks(Blocks.REINFORCED_DEEPSLATE))
    // .where("A", Predicates.blocks(Blocks.STONE_BRICKS))
    // .where("E", Predicates.blocks(Blocks.SOUL_FIRE))
    // .where("I", Predicates.controller(Predicates.blocks(definition.get())))
    // .where("C", Predicates.blocks(GTLBlocks.MAGIC_COIL_LOW_BLOCK.get()))
    // .build())
    // .workableCasingRenderer(new ResourceLocation("minecraft", "block/stone_bricks"), new
    /// ResourceLocation("minecraft", "block/stone_bricks"))
    // .register();

    /// *海洋祭坛*
    // public final static MultiblockMachineDefinition OCEAN_SLTAR = REGISTRATE.multiblock("ocean_sltar",
    /// WorkableElectricMultiblockMachine::new)
    // .rotationState(RotationState.NON_Y_AXIS)
    // .allowExtendedFacing(false)
    // .recipeType(GTLRecipeTypes.THE_OCEAN_CALLS)
    // .appearanceBlock(() -> Blocks.PRISMARINE_BRICKS)
    // .pattern(definition -> FactoryBlockPattern.start()
    // .aisle("KKKKKKKKKKKKKKKK", " ", " ", " ", " ", " ", " ", " ", " ")
    // .aisle("KCCDCCDCCDCCDCCK", " CCCCCCCCCCCCCC ", " ", " ", " ", " ", " ", " ", " ")
    // .aisle("KCEEEEEEEEEEEECK", " CFFFFFFFFFFFFC ", " CCCCCCCCCCCC ", " ", " ", " ", " ", " ", " ")
    // .aisle("KDEGCCCCCCCGGECK", " CFAAAAAAAAAAFC ", " CEEEEEEEEEEC ", " CCCCCCCCCC ", " ", " ", " ", " ", " ")
    // .aisle("KCECHHCHHCCCGECK", " CFCGGCGGCGGAFC ", " CCGGCGGCGGEC ", " CIIIIIIIIC ", " C C ", " C C ", " C C ", " ",
    /// " ")
    // .aisle("KCEGCCCCCCCCCECK", " CFEEEEEEEEGAFC ", " CGFFFFFFFGEC ", " CIIIIIIIIC ", " ", " ", " ", " C C ", " ")
    // .aisle("KDEGAAAAACCCCECK", " CFFFFFFFFECAFC ", " CGAAAAAAFCEC ", " CIIIIIIIIC ", " ", " ", " ", " D D ", " CIIC
    /// ")
    // .aisle("KCEGAFFFFACHCECK", " CFAAGAGAFEGAFC ", " CGGAGAGAFGEC ", " CIIIIIIIIC ", " ", " ", " ", " ", " I I ")
    // .aisle("KCEGAFFFFACHCECK", " CFAAGAGAFEGAFC ", " CGGAGAGAFGEC ", " CIIIIIIIIC ", " ", " ", " ", " ", " I I ")
    // .aisle("KDEGAAAAACCCCECK", " CFFFFFFFFECAFC ", " CGAAAAAAFCEC ", " CIIIIIIIIC ", " ", " ", " ", " D D ", " CIIC
    /// ")
    // .aisle("KCEGCCCCCCCCCECK", " CFEEEEEEEEGAFC ", " CGFFFFFFFGEC ", " CIIIIIIIIC ", " ", " ", " ", " C C ", " ")
    // .aisle("KCECHHCHHCCCGECK", " CFCGGCGGCGGAFC ", " CCGGCGGCGGEC ", " CIIIIIIIIC ", " C C ", " C C ", " C C ", " ",
    /// " ")
    // .aisle("KDEGCCCCCCCGGECK", " CFAAAAAAAAAAFC ", " CEEEEEEEEEEC ", " CCCCCCCCCC ", " ", " ", " ", " ", " ")
    // .aisle("KCEEEEEEEEEEEECK", " CFFFFFFFFFFFFC ", " CCCCCCCCCCCC ", " ", " ", " ", " ", " ", " ")
    // .aisle("KCCDCCDCCDCCDCCK", " CCCCCCCCCCCCCC ", " ", " ", " ", " ", " ", " ", " ")
    // .aisle("GKKKKKKKKKKKKKKK", " ", " ", " ", " ", " ", " ", " ", " ")
    // .where("E", Predicates.blocks(GTLBlocks.MAGIC_COIL_LOW_BLOCK.get()))
    // .where("H", Predicates.blocks(GTLBlocks.NON_ATTRIBUTE_MAGIC_CRYSTALS_BLOCK.get()))
    // .where("A", Predicates.blocks(GTLBlocks.OCEAN_MAGIC_CRYSTALS_BLOCK.get()))
    // .where("G", Predicates.controller(Predicates.blocks(definition.get())))
    // .where("C", Predicates.blocks(Blocks.PRISMARINE_BRICKS))
    // .where("K", Predicates.blocks(Blocks.PRISMARINE_BRICKS)
    // .or(Predicates.autoAbilities(definition.getRecipeTypes())))
    // .where("F", Predicates.blocks(GTLBlocks.MAGIC_MECHANICAL_LOW_CUBE.get()))
    // .where("D", Predicates.blocks(Blocks.SEA_LANTERN))
    // .where("I", Predicates.blocks(Blocks.PRISMARINE))
    // .build())
    // .workableCasingRenderer(new ResourceLocation("minecraft", "block/prismarine_bricks"), new
    /// ResourceLocation("minecraft", "block/prismarine_bricks"))
    // .register();

    /// *秘法启示台*
    public final static MultiblockMachineDefinition MYSTIC_REVELATION_PLATFORM = REGISTRATE.multiblock("mystic_revelation_platform", WorkableElectricMultiblockMachine::new)
            .rotationState(RotationState.NON_Y_AXIS)
            .allowExtendedFacing(false)
            .recipeType(GTLRecipeTypes.DARK_PEARL_QIHUI)
            .appearanceBlock(GTBlocks.CASING_STAINLESS_CLEAN)
            .pattern(definition -> FactoryBlockPattern.start()
                    .aisle("                     ", "                     ", "                     ", "                     ", "                     ", "                     ", "                     ", "                     ", "                     ", "                     ", "                     ", "                     ", "                     ", "          B          ", "          B          ", "          B          ", "                     ", "                     ", "                     ", "                     ", "                     ", "                     ", "                     ", "                     ", "                     ", "                     ", "                     ")
                    .aisle("                     ", "                     ", "                     ", "                     ", "                     ", "                     ", "                     ", "                     ", "                     ", "                     ", "                     ", "         B B         ", "         B B         ", "         BBB         ", "          E          ", "          B          ", "                     ", "                     ", "                     ", "                     ", "                     ", "                     ", "                     ", "                     ", "                     ", "                     ", "                     ")
                    .aisle("                     ", "                     ", "                     ", "                     ", "                     ", "                     ", "                     ", "                     ", "                     ", "                     ", "                     ", "         B B         ", "         DED         ", "         EEE         ", "         EEE         ", "         DED         ", "          D          ", "                     ", "                     ", "                     ", "                     ", "                     ", "                     ", "                     ", "                     ", "                     ", "                     ")
                    .aisle("                     ", "                     ", "                     ", "                     ", "                     ", "                     ", "                     ", "                     ", "                     ", "                     ", "         D D         ", "         EEE         ", "         EDE         ", "         D D         ", "         D D         ", "         EDE         ", "         EEE         ", "         DED         ", "          D          ", "                     ", "                     ", "                     ", "                     ", "                     ", "                     ", "                     ", "                     ")
                    .aisle("                     ", "                     ", "                     ", "                     ", "                     ", "                     ", "                     ", "                     ", "         D D         ", "        DDFDD        ", "        DFFFD        ", "         D D         ", "                     ", "                     ", "                     ", "                     ", "                     ", "         DED         ", "          E          ", "                     ", "                     ", "                     ", "                     ", "                     ", "                     ", "                     ", "                     ")
                    .aisle("                     ", "                     ", "                     ", "                     ", "                     ", "                     ", "         D D         ", "        DEEED        ", "        EEEEE        ", "        EEFEE        ", "       FFEGEFF       ", "         H H         ", "                     ", "                     ", "                     ", "                     ", "                     ", "          I          ", "          E          ", "                     ", "                     ", "                     ", "                     ", "                     ", "                     ", "                     ", "                     ")
                    .aisle("                     ", "                     ", "                     ", "                     ", "          B          ", "          B          ", "          J          ", "          J          ", "         JJJ         ", "       HJJFJJH       ", "      FEEHKHEEF      ", "       DH   HD       ", "                     ", "                     ", "                     ", "                     ", "                     ", "                     ", "          D          ", "                     ", "                     ", "                     ", "                     ", "                     ", "                     ", "                     ", "                     ")
                    .aisle("                     ", "                     ", "                     ", "                     ", "          B          ", "          JM         ", "        MMJM         ", "        MJJJ         ", "       HJJFJJH       ", "      HJJLFLJJH      ", "     FEEHGKGHEEF     ", "      DF  G  FD      ", "                     ", "                     ", "                     ", "                     ", "                     ", "                     ", "                     ", "                     ", "                     ", "                     ", "                     ", "                     ", "                     ", "                     ", "                     ")
                    .aisle("                     ", "                     ", "                     ", "                     ", "          J          ", "         JJM         ", "        JJJJ M       ", "     D  JJJJJM D     ", "     E JJDFDJJ E     ", "    DEJJLDGDLJJED    ", "    DFEHEEGEEHEFD    ", "      H H G H H      ", "          G          ", "                     ", "                     ", "                     ", "                     ", "                     ", "          N          ", "          NN         ", "         NNN         ", "         NNN         ", "          N          ", "          N          ", "                     ", "                     ", "                     ")
                    .aisle("                     ", "                     ", "                     ", "          J          ", "         JJJ         ", "        JJJJ         ", "     D JJJJJJM D     ", "     E JJJJJJJ E     ", "    DEJJDHFHDJJED    ", "    DEJLD H DLJED    ", "   DFEHGE   EGHEFD   ", " BBEDH         HDEBB ", " BDE             EDB ", " BED             DEB ", "  ED             DE  ", "  DE      N      ED  ", "   E      N      E   ", "   DD     NN    DD   ", "         NAN         ", "         NAAN        ", "        NAAAN        ", "        NAAAN        ", "         NAN         ", "         NAN         ", "          NN         ", "          N          ", "                     ")
                    .aisle("          M          ", "          B          ", "        MMJ          ", "        MJJJ         ", "      BBJJJJJBB      ", "      BJJJJJJJB      ", "      JJJJJJJJJ      ", "     EJJJJJJJJJE     ", "     EJFFFFFFFJE     ", "    FFFFGH HGFFFF    ", "    FGKKG   GKKGF    ", "   E   GG   GG   E   ", "  ED    G   G    DE  ", "BBE               EBB", "BCE       N       EEB", "BBED     NAN     DEBB", "  DE     NAN     ED  ", "   EEI   NAAN  IEE   ", "   DEED NAAAN DEED   ", "        NAAAN        ", "        NAAAN        ", "        NAAAN        ", "        NAAAN        ", "         NAAN        ", "         NAAN        ", "         NAN         ", "          N          ")
                    .aisle("                     ", "                     ", "                     ", "          J          ", "          JJ         ", "        JJJJJ        ", "     D JJJJJJJ D     ", "     E JJJJJJJJE     ", "    DEJJDHFHDJJED    ", "    DEJLD H DLJED    ", "   DFEHGE   EGHEFD   ", " BBEDH         HDEBB ", " BDE             EDB ", " BED             DEB ", "  ED             DE  ", "  DE      N      ED  ", "   E      N      E   ", "   DD    NAN    DD   ", "         NAN         ", "        NAAN         ", "        NAAAN        ", "         NAAN        ", "         NAAN        ", "         NAN         ", "          NN         ", "          N          ", "                     ")
                    .aisle("                     ", "                     ", "                     ", "                     ", "          J          ", "         JJJ         ", "        JJJJM        ", "     D  JJJJMM D     ", "     E JJDFDJJ E     ", "    DEJJLDGDLJJED    ", "    DFEHEEGEEHEFD    ", "      H H G H H      ", "          G          ", "                     ", "                     ", "                     ", "                     ", "          N          ", "          N          ", "         NN          ", "         NNN         ", "          NN         ", "          NN         ", "          N          ", "                     ", "                     ", "                     ")
                    .aisle("                     ", "                     ", "                     ", "                     ", "          B          ", "          J          ", "        MMJJ         ", "        MJJJM        ", "       HJJFJJH       ", "      HJJLFLJJH      ", "     FEEHGKGHEEF     ", "      DF  G  FD      ", "                     ", "                     ", "                     ", "                     ", "                     ", "                     ", "                     ", "                     ", "                     ", "                     ", "                     ", "                     ", "                     ", "                     ", "                     ")
                    .aisle("                     ", "                     ", "                     ", "                     ", "          B          ", "          B          ", "          J          ", "         JJJ         ", "        JJJJ         ", "       HJJFJJH       ", "      FEEHKHEEF      ", "       DH   HD       ", "                     ", "                     ", "                     ", "                     ", "                     ", "                     ", "          D          ", "                     ", "                     ", "                     ", "                     ", "                     ", "                     ", "                     ", "                     ")
                    .aisle("                     ", "                     ", "                     ", "                     ", "                     ", "                     ", "         D D         ", "        DEEED        ", "        EEEEE        ", "        EEFEE        ", "       FFEGEFF       ", "         H H         ", "                     ", "                     ", "                     ", "                     ", "                     ", "          I          ", "          E          ", "                     ", "                     ", "                     ", "                     ", "                     ", "                     ", "                     ", "                     ")
                    .aisle("                     ", "                     ", "                     ", "                     ", "                     ", "                     ", "                     ", "                     ", "         D D         ", "        DDFDD        ", "        DFFFD        ", "         D D         ", "                     ", "                     ", "                     ", "                     ", "                     ", "         DDD         ", "          E          ", "                     ", "                     ", "                     ", "                     ", "                     ", "                     ", "                     ", "                     ")
                    .aisle("                     ", "                     ", "                     ", "                     ", "                     ", "                     ", "                     ", "                     ", "                     ", "                     ", "         D D         ", "         EEE         ", "         EDE         ", "         D D         ", "         D D         ", "         EDE         ", "         EEE         ", "         DED         ", "          D          ", "                     ", "                     ", "                     ", "                     ", "                     ", "                     ", "                     ", "                     ")
                    .aisle("                     ", "                     ", "                     ", "                     ", "                     ", "                     ", "                     ", "                     ", "                     ", "                     ", "                     ", "         B B         ", "         DED         ", "         EEE         ", "         EEE         ", "         DED         ", "          D          ", "                     ", "                     ", "                     ", "                     ", "                     ", "                     ", "                     ", "                     ", "                     ", "                     ")
                    .aisle("                     ", "                     ", "                     ", "                     ", "                     ", "                     ", "                     ", "                     ", "                     ", "                     ", "                     ", "         B B         ", "         B B         ", "         BBB         ", "          E          ", "          B          ", "                     ", "                     ", "                     ", "                     ", "                     ", "                     ", "                     ", "                     ", "                     ", "                     ", "                     ")
                    .aisle("                     ", "                     ", "                     ", "                     ", "                     ", "                     ", "                     ", "                     ", "                     ", "                     ", "                     ", "                     ", "                     ", "          B          ", "          B          ", "          B          ", "                     ", "                     ", "                     ", "                     ", "                     ", "                     ", "                     ", "                     ", "                     ", "                     ", "                     ")
                    .where("J", Predicates.blocks(Blocks.DIRT))
                    .where("K", Predicates.blocks(GTBlocks.TREATED_WOOD_SLAB.get()))
                    .where("F", Predicates.blocks(Blocks.CHISELED_STONE_BRICKS))
                    .where("I", Predicates.blocks(Blocks.STONE_BRICK_SLAB))
                    .where("C", Predicates.controller(Predicates.blocks(definition.get())))
                    .where("G", Predicates.blocks(GTBlocks.TREATED_WOOD_STAIRS.get()))
                    .where("E", Predicates.blocks(Blocks.STONE_BRICKS))
                    .where("H", Predicates.blocks(Blocks.STONE_SLAB))
                    .where("D", Predicates.blocks(Blocks.STONE_BRICK_STAIRS))
                    .where("N", Predicates.blocks(Blocks.PURPLE_STAINED_GLASS))
                    .where("B", Predicates.blocks(Blocks.COBBLESTONE_WALL))
                    .where("M", Predicates.blocks(Blocks.OAK_FENCE))
                    .where("A", Predicates.blocks(GTLBlocks.MAGIC_MECHANICAL_LOW_CUBE.get()))
                    .where("L", Predicates.blocks(Blocks.SEA_LANTERN))
                    .build())
            .workableCasingRenderer(new ResourceLocation("minecraft", "block/stone_bricks"), GTCEu.id("block/multiblock/vacuum_freezer"))
            .register();

    /// *注魔祭坛*
    public final static MultiblockMachineDefinition INFUSED_ALTAR = REGISTRATE.multiblock("infused_altar", WorkableElectricMultiblockMachine::new)
            .rotationState(RotationState.NON_Y_AXIS)
            .allowExtendedFacing(false)
            .recipeType(GTLRecipeTypes.INFUSION_RITUAL)
            .appearanceBlock(GTBlocks.CASING_STAINLESS_CLEAN)
            .pattern(definition -> FactoryBlockPattern.start()
                    .aisle("         AAABAAAAA         ", "         ABAAABABB         ", "                           ", "                           ", "                           ", "                           ", "                           ", "                           ", "                           ", "                           ", "                           ", "                           ")
                    .aisle("       ABCCCCCCCCCAA       ", "       AACCCCCCCCCAB       ", "         DBBBABABD         ", "                           ", "                           ", "                           ", "                           ", "                           ", "                           ", "                           ", "                           ", "                           ")
                    .aisle("      ACCC       CCCA      ", "      BCCC       CCCA      ", "       DBAEEEEEEEABD       ", "          DDDDDDD          ", "                           ", "                           ", "                           ", "                           ", "                           ", "                           ", "                           ", "                           ")
                    .aisle("    AACC           CCAA    ", "    BACC           CCBA    ", "      DAEECCCCCCCEEAD      ", "        DDAAAAAAADD        ", "                           ", "                           ", "                           ", "                           ", "                           ", "                           ", "                           ", "                           ")
                    .aisle("   BCCC             CCCB   ", "   ACCC             CCCA   ", "    DBAECC EEEEE CCEABD    ", "       DAA AAAAA AAD       ", "          F     F          ", "                           ", "                           ", "                           ", "                           ", "                           ", "                           ", "                           ")
                    .aisle("   AC                 CA   ", "   AC                 CA   ", "    AEEC EECCCCCEE CEEA    ", "     DDA BAAAABAAA ADD     ", "        F         F        ", "                           ", "                           ", "                           ", "                           ", "                           ", "                           ", "                           ")
                    .aisle("  ACC                 CCA  ", "  BCC                 CCB  ", "   DBECEECC     CCEECEBD   ", "     DABAABEEEEEBABABD     ", "         DDDDDDDDD         ", "                           ", "                           ", "                           ", "                           ", "                           ", "                           ", "                           ")
                    .aisle(" ACC   G           G   CCA ", " ACC   G           G   CCA ", "  DAECEGC         CGECEAD  ", "    DBAGAEECCCCCEEAGAAD    ", "       GDAAAABAAAADG       ", "       G           G       ", "       G           G       ", "       G           G       ", "       G           G       ", "       G           G       ", "       G           G       ", "       H           H       ")
                    .aisle(" AC                     CB ", " BC                     CA ", "  BEC EC           CE CEB  ", "   DA BBE CEEEEEC EAA AD   ", "     F DA AABABAB AD F     ", "         I       I         ", "                           ", "                           ", "                           ", "                           ", "                           ", "                           ")
                    .aisle("ACC        J   J        CCA", "ACC        J   J        CCA", " DAECEC    J   J    CECEAD ", "   DBAAE CEJCCCJEC EBAAD   ", "      DA ABJCCCJAA AD      ", "        I  JDDDJ  I        ", "           J   J           ", "           J   J           ", "           J   J           ", "           K   K           ", "                           ", "                           ")
                    .aisle("BC                       CA", "AC                       CB", " BEC EC             CE CEB ", "  DA BAECECCLLLCCECEAA AD  ", "    F DABACCEEECCBAAD F    ", "          DDAAADD          ", "                           ", "                           ", "                           ", "                           ", "                           ", "                           ")
                    .aisle("AC       J       J       CA", "AC       J       J       CA", " AECEC   J       J   CECEA ", "  DAAAECEJCLMMMLCJECEBAAD  ", "      DAAJCECCCECJABD      ", "         JDACCCADJ         ", "         J  DDD  J         ", "         J       J         ", "         J       J         ", "         K       K         ", "                           ", "                           ")
                    .aisle("AC                       CB", "BC                       CA", " BECEC               CECEB ", "  ABBAECECLMLLLMLCECEABAA  ", "      DBACECEEECECBBD      ", "         DACEEECAD         ", "           DAAAD           ", "                           ", "                           ", "                           ", "                           ", "                           ")
                    .aisle("AC                       CA", "AC                       CA", " AE EC               CE EA ", "  A ABECECLMLNLMLCECEAA A  ", "   O  DAACECEEECECAAD  P   ", "         DACEEECAD         ", "           DAAAD           ", "             Q             ", "                           ", "                           ", "                           ", "                           ")
                    .aisle("BC                       CA", "AC                       CB", " BECEC               CECEA ", "  ABAAECECLMLLLMLCECEBABA  ", "      DABCECEEECECAAD      ", "         DACEEECAD         ", "           DAAAD           ", "                           ", "                           ", "                           ", "                           ", "                           ")
                    .aisle("AC       J       J       CA", "AC       J       J       CA", " AECEC   J       J   CECEB ", "  DABAECEJCLMMMLCJECEAAAD  ", "      DAAJCECCCECJBAD      ", "         JDACCCADJ         ", "         J  DDD  J         ", "         J       J         ", "         J       J         ", "         K       K         ", "                           ", "                           ")
                    .aisle("AC                       CA", "AC                       CB", " BEC EC             CE CEA ", "  DA ABECECCLLLCCECEBA BD  ", "    F DAABCCEEECCAAAD F    ", "          DDAAADD          ", "                           ", "                           ", "                           ", "                           ", "                           ", "                           ")
                    .aisle("ACC        J   J        CCA", "BCC        J   J        CCB", " DAECEC    J   J    CECEBD ", "   DAAAE CEJCCCJEC EAABD   ", "      DA ABJCCCJAB AD      ", "        I  JDDDJ  I        ", "           J   J           ", "           J   J           ", "           J   J           ", "           K   K           ", "                           ", "                           ")
                    .aisle(" BC                     CA ", " AC                     CB ", "  BEC EC           CE CEA  ", "   DA AAE CEEEEEC EBA AD   ", "     F DA AABABAA AD F     ", "         I       I         ", "                           ", "                           ", "                           ", "                           ", "                           ", "                           ")
                    .aisle(" ACC   G           G   CCA ", " ACC   G           G   CCA ", "  DAECEGC         CGECEAD  ", "    DAAGAEECCCCCEEAGAAD    ", "       GDAAAAAABAADG       ", "       G           G       ", "       G           G       ", "       G           G       ", "       G           G       ", "       G           G       ", "       G           G       ", "       H           H       ")
                    .aisle("  BCC                 CCA  ", "  ACC                 CCB  ", "   DBECEECC     CCEECEBD   ", "     DAAABAEEEEEABAAAD     ", "         DDDDDDDDD         ", "                           ", "                           ", "                           ", "                           ", "                           ", "                           ", "                           ")
                    .aisle("   AC                 CA   ", "   BC                 CA   ", "    AEEC EECCCCCEE CEEA    ", "     DDA AABAAABAA ADD     ", "        F         F        ", "                           ", "                           ", "                           ", "                           ", "                           ", "                           ", "                           ")
                    .aisle("   ACCC             CCCA   ", "   ACCC             CCCB   ", "    DAAECC EEEEE CCEBAD    ", "       DBA AABBA AAD       ", "          F     F          ", "                           ", "                           ", "                           ", "                           ", "                           ", "                           ", "                           ")
                    .aisle("    AACC           CCAA    ", "    BACC           CCBA    ", "      DAEECCCCCCCEEAD      ", "        DDABAABABDD        ", "                           ", "                           ", "                           ", "                           ", "                           ", "                           ", "                           ", "                           ")
                    .aisle("      ACCC       CCCA      ", "      BCCC       CCCA      ", "       DAAEEEEEEEABD       ", "          DDDDDDD          ", "                           ", "                           ", "                           ", "                           ", "                           ", "                           ", "                           ", "                           ")
                    .aisle("       AACCCCCCCCCAA       ", "       ABCCCCCCCCCAB       ", "         DAABABAAD         ", "                           ", "                           ", "                           ", "                           ", "                           ", "                           ", "                           ", "                           ", "                           ")
                    .aisle("         AAAABAAAA         ", "         AABAAABAB         ", "                           ", "                           ", "                           ", "                           ", "                           ", "                           ", "                           ", "                           ", "                           ", "                           ")
                    .where("J", Predicates.blocks(GTBlocks.STONE_BLOCKS.get(StoneBlockType.WINDMILL_B, StoneTypes.RED_GRANITE).get()))
                    .where("O", Predicates.blocks(GTMachines.ITEM_EXPORT_BUS[0].getBlock()))
                    .where("F", Predicates.blocks(GTMachines.ITEM_IMPORT_BUS[0].getBlock()))
                    .where("I", Predicates.blocks(GTMachines.FLUID_IMPORT_HATCH[0].getBlock()))
                    .where("E", Predicates.blocks(Registries.getBlock("gtlcore:magic_mechanical_low_cube")))
                    .where("K", Predicates.blocks(Registries.getBlock("gtceu:chiseled_red_granite")))
                    .where("D", Predicates.blocks(Registries.getBlock("minecraft:deepslate_brick_slab")))
                    .where("A", Predicates.blocks(Registries.getBlock("minecraft:deepslate_bricks")))
                    .where("B", Predicates.blocks(Registries.getBlock("minecraft:cracked_deepslate_bricks")))
                    .where("N", Predicates.blocks(Registries.getBlock("gtceu:lv_input_hatch")))
                    .where("L", Predicates.blocks(Registries.getBlock("gtceu:polished_marble")))
                    .where("M", Predicates.blocks(Registries.getBlock("gtceu:polished_red_granite")))
                    .where("Q", Predicates.controller(Predicates.blocks(definition.get())))
                    .where("P", Predicates.blocks(Registries.getBlock("gtceu:ulv_output_bus")))
                    .where("G", Predicates.blocks(Registries.getBlock("gtceu:marble_windmill_a")))
                    .where("C", Predicates.blocks(Registries.getBlock("gtlcore:magic_coil_low_block")))
                    .where("H", Predicates.blocks(Registries.getBlock("gtceu:chiseled_marble")))
                    .build())
            .workableCasingRenderer(new ResourceLocation("minecraft", "block/deepslate_bricks"), GTCEu.id("block/multiblock/vacuum_freezer"))
            .register();

    /// *原始法师塔*
    public final static MultiblockMachineDefinition MEGA_TOWER = REGISTRATE.multiblock("mage_tower", WorkableElectricMultiblockMachine::new)
            .rotationState(RotationState.NON_Y_AXIS)
            .allowExtendedFacing(false)
            .recipeType(GTLRecipeTypes.INFUSION_RITUAL)
            .appearanceBlock(GTBlocks.CASING_STAINLESS_CLEAN)
            .pattern(definition -> FactoryBlockPattern.start()
                    .aisle("                           ", "                           ", "                           ", "                           ", "                           ", "                           ", "                           ", "                           ", "                           ", "                           ", "                           ", "                           ", "                           ", "                           ", "                           ", "                           ", "                           ", "                           ", "                           ", "                           ", "                           ", "                           ", "                           ", "                           ", "                           ", "                           ", "                           ", "                           ", "                           ", "                           ", "                           ", "                           ", "                           ", "                           ", "                           ", "                           ", "                           ", "                           ", "                           ", "                           ", "                           ", "                           ", "                           ", "                           ", "                           ", "                           ", "                           ", "                           ", "             A             ", "             A             ", "                           ", "                           ", "                           ", "                           ", "                           ", "                           ", "                           ", "                           ", "                           ", "                           ", "                           ")
                    .aisle("                           ", "                           ", "                           ", "                           ", "                           ", "                           ", "                           ", "                           ", "                           ", "                           ", "                           ", "                           ", "                           ", "                           ", "                           ", "                           ", "                           ", "                           ", "                           ", "                           ", "                           ", "                           ", "                           ", "                           ", "                           ", "                           ", "                           ", "                           ", "                           ", "                           ", "                           ", "                           ", "                           ", "                           ", "                           ", "                           ", "                           ", "                           ", "                           ", "                           ", "                           ", "                           ", "                           ", "                           ", "                           ", "                           ", "            A A            ", "            AAA            ", "             A             ", "                           ", "                           ", "                           ", "                           ", "                           ", "                           ", "                           ", "                           ", "                           ", "                           ", "                           ", "                           ")
                    .aisle("                           ", "                           ", "                           ", "                           ", "                           ", "                           ", "                           ", "                           ", "                           ", "                           ", "                           ", "                           ", "                           ", "                           ", "                           ", "                           ", "                           ", "                           ", "                           ", "                           ", "                           ", "                           ", "                           ", "                           ", "                           ", "                           ", "                           ", "                           ", "                           ", "                           ", "                           ", "                           ", "                           ", "                           ", "                           ", "                           ", "                           ", "                           ", "                           ", "                           ", "                           ", "                           ", "                           ", "           A   A           ", "           AA AA           ", "            A A            ", "            A A            ", "            AAA            ", "             A             ", "                           ", "                           ", "                           ", "                           ", "                           ", "                           ", "                           ", "                           ", "                           ", "                           ", "                           ", "                           ")
                    .aisle("                           ", "                           ", "                           ", "                           ", "                           ", "                           ", "                           ", "                           ", "                           ", "                           ", "                           ", "                           ", "                           ", "                           ", "                           ", "                           ", "                           ", "                           ", "                           ", "                           ", "                           ", "                           ", "                           ", "                           ", "                           ", "                           ", "                           ", "                           ", "                           ", "                           ", "                           ", "                           ", "                           ", "                           ", "                           ", "                           ", "                           ", "                           ", "                           ", "                           ", "          A     A          ", "          A     A          ", "          AACCCAA          ", "           A   A           ", "           AA AA           ", "            A A            ", "            ACA            ", "            AAA            ", "             A             ", "                           ", "                           ", "                           ", "                           ", "                           ", "                           ", "                           ", "                           ", "                           ", "                           ", "             A             ", "             A             ")
                    .aisle("                           ", "                           ", "                           ", "                           ", "                           ", "                           ", "                           ", "                           ", "                           ", "                           ", "                           ", "                           ", "                           ", "                           ", "                           ", "                           ", "                           ", "                           ", "                           ", "                           ", "                           ", "                           ", "                           ", "                           ", "                           ", "                           ", "                           ", "                           ", "                           ", "                           ", "                           ", "                           ", "                           ", "                           ", "                           ", "                           ", "           DDDDD           ", "           EEEEE           ", "           E   E           ", "         AAE   EAA         ", "         AAE   EAA         ", "          AFDDDFA          ", "          AAGGGAA          ", "           A   A           ", "           AA AA           ", "            ACA            ", "            ABA            ", "            AAA            ", "             A             ", "                           ", "                           ", "                           ", "                           ", "                           ", "                           ", "                           ", "                           ", "            A A            ", "            AAA            ", "             A             ", "                           ")
                    .aisle("           HHHHH           ", "           HIHIH           ", "           H H H           ", "                           ", "                           ", "                           ", "                           ", "                           ", "                           ", "                           ", "                           ", "                           ", "                           ", "                           ", "                           ", "                           ", "                           ", "                           ", "                           ", "                           ", "                           ", "                           ", "             I             ", "                           ", "                           ", "                           ", "                           ", "                           ", "                           ", "                           ", "                           ", "                           ", "                           ", "                           ", "                           ", "                           ", "           FFFFF           ", "           JKKKJ           ", "           JKKKJ           ", "         AAJKKKJAA         ", "         AAJKKKJAA         ", "          AJKKKJA          ", "          AJFFFJA          ", "           AFFFA           ", "           AFKFA           ", "            AFA            ", "            A A            ", "            AAA            ", "             A             ", "                           ", "                           ", "                           ", "                           ", "                           ", "           A   A           ", "           AA AA           ", "            A A            ", "            A A            ", "            A A            ", "             A             ", "                           ")
                    .aisle("         HHLLLLLHH         ", "         HILLLLLIH         ", "         H HHHHH H         ", "           H H H           ", "           HHHHH           ", "           L L L           ", "                           ", "                           ", "                           ", "                           ", "                           ", "            LIL            ", "            L L            ", "                           ", "                           ", "                           ", "                           ", "                           ", "                           ", "                           ", "                           ", "                           ", "             L             ", "                           ", "                           ", "                           ", "                           ", "                           ", "                           ", "                           ", "                           ", "                           ", "             D             ", "                           ", "                           ", "           F F F           ", "           FFFFF           ", "           F   F           ", "           K   K           ", "         AAF   FAA         ", "         AA     AA         ", "          A     A          ", "          A     A          ", "           A   A           ", "           A   A           ", "            A A            ", "            A A            ", "            AAA            ", "             A             ", "                           ", "                           ", "                           ", "          A     A          ", "          AA   AA          ", "           ACCCA           ", "           A   A           ", "            A A            ", "            A A            ", "            ACA            ", "             A             ", "                           ")
                    .aisle("        HLLLLLLLLLH        ", "        HLL     LLH        ", "        HHHH H HHHH        ", "         H HHHHH H         ", "         HHH H HHH         ", "         LILILILIL         ", "           L L L           ", "           L L L           ", "           L L L           ", "                           ", "           L L L           ", "           LHHHL           ", "           L   L           ", "                           ", "                           ", "                           ", "                           ", "                           ", "                           ", "                           ", "                           ", "             L             ", "             L             ", "                           ", "                           ", "                           ", "                           ", "                           ", "                           ", "                           ", "                           ", "             F             ", "             D             ", "           F F F           ", "           F F F           ", "           F F F           ", "           FFFFF           ", "           J   J           ", "           J   J           ", "         AAJ   JAA         ", "         AAJ   JAA         ", "          AJ   JA          ", "          AJ   JA          ", "           A   A           ", "           A   A           ", "            A A            ", "            A A            ", "            AAA            ", "             A             ", "          FDDDDDF          ", "         AAEEEEEAA         ", "          AE   EA          ", "          AE   EA          ", "          AFDDDFA          ", "           AGGGA           ", "           A   A           ", "            A A            ", "            ACA            ", "            ABA            ", "             A             ", "                           ")
                    .aisle("       HLLLLLLLLLLLH       ", "       HL         LH       ", "       HHH       HHH       ", "        HHH     HHH        ", "        HH       HH        ", "        ILHHHHHHHLI        ", "         LHHHHHHHL         ", "         LHHHHHHHL         ", "         LHLHLHLHL         ", "          HLHLHLH          ", "          HLHLHLH          ", "          HHHHHHH          ", "          H M M H          ", "          M M M M          ", "          M NNN M          ", "          M     M          ", "          M     M          ", "          M     M          ", "          M     M          ", "          LL   LL          ", "           LL LL           ", "           LLLLL           ", "           M L M           ", "           EOOOE           ", "           E   E           ", "           E   E           ", "          FE   EF          ", "          FE   EF          ", "          FF   FF          ", "           F   F           ", "           FFCFF           ", "           FFFFF           ", "           FPFPF           ", "           FDFDF           ", "           F F F           ", "           F F F           ", "           FFFFF           ", "           F   F           ", "           K   K           ", "         AAF   FAA         ", "         AA     AA         ", "          A     A          ", "          A     A          ", "           A   A           ", "           A   A           ", "            A A            ", "            A A            ", "            AAA            ", "          F  A  F          ", "          FDDDDDF          ", "         AAJKKKJAA         ", "          AJKKKJA          ", "          AJKKKJA          ", "          AJKKKJA          ", "           AFFFA           ", "           AFFFA           ", "            AKA            ", "            AJA            ", "            A A            ", "             A             ", "                           ")
                    .aisle("      HLLLLLLLLLLLLLH      ", "      HL           LH      ", "      HHH         HHH      ", "       HH         HH       ", "       HH         HH       ", "       LLH       HLL       ", "        LH       HL        ", "        LH       HL        ", "        LL       LL        ", "         L       L         ", "         L       L         ", "          LLLHLLL          ", "          LLLQLLL          ", "          LLLQLLL          ", "          LLHLHLL          ", "          LM M ML          ", "          LM M ML          ", "          LM M ML          ", "          LL M LL          ", "          LLLMLLL          ", "          LLLLLLL          ", "          LLLLLLL          ", "          MJLLLJM          ", "          EJGGGJE          ", "          EJ   JE          ", "          EJE EJE          ", "          FJE EJF          ", "          FJE EJF          ", "          FJE EJF          ", "          EJECEJE          ", "          EJFBFJE          ", "          EJ   JE          ", "          EJFFFJE          ", "          EJFFFJE          ", "          EJEFEJE          ", "          EJEFEJE          ", "          EJFFFJE          ", "          EJ   JE          ", "          EJ   JE          ", "    AAAAAAAJ   JAAAAAAA    ", "    AAAAAAAJ   JAAAAAAA    ", "          AJ   JA          ", "          AJ   JA          ", "           A   A           ", "           A   A           ", "            A A            ", "          F A A F          ", "          F AAA F          ", "          F  A  F          ", "          FDDDDDF          ", "       AAAA     AAAA       ", "          A     A          ", "          A     A          ", "          A     A          ", "           A   A           ", "           A   A           ", "            A A            ", "            A A            ", "            A A            ", "             A             ", "                           ")
                    .aisle("      HLLLLLLLLLLLLLH      ", "      IL           LI      ", "       H           H       ", "        H         H        ", "       H           H       ", "       IH         HI       ", "        H         H        ", "        H         H        ", "        H         H        ", "        H         H        ", "        H         H        ", "        HLHHHHHHHLH        ", "        HL       LH        ", "        ML       LM        ", "        ML HHHHH LM        ", "        ML HRHRH LM        ", "        ML HRHRH LM        ", "        ML HRHRH LM        ", "        ML  HHH  LM        ", "        LL  HHH  LL        ", "         L       L         ", "         LL     LL         ", "         MJFFFFFJM         ", "         EJ FFF JE         ", "         EJ FKF JE         ", "         EJ FKF JE         ", "        FFJ FKF JFF        ", "        FFJ FFF JFF        ", "        FFJ FKF JFF        ", "         EJ FFF JE         ", "         EJ     JE         ", "         EJ     JE         ", "         EJ     JE         ", "         EJ     JE         ", "         EJ     JE         ", "         EJ     JE         ", "         EJFFFFFJE         ", "         EJ     JE         ", "         EJ     JE         ", "    AAAAAAJ     JAAAAAA    ", "   AAAAAAAJ     JAAAAAAA   ", "   AAAAAAAJ     JAAAAAAA   ", "   AAAAAAAJ     JAAAAAAA   ", "          JFFFFFJ          ", "          JFFFFFJ          ", "          JFFFFFJ          ", "         FJFFFFFJF         ", "         FJFFFFFJF         ", "        FFJFFFFFJFF        ", "       FFFJFFFFFJFFF       ", "       AAAA     AAAA       ", "       AAAA     AAAA       ", "      AAAAA     AAAAA      ", "      AAAAA     AAAAA      ", "           A   A           ", "           A   A           ", "            A A            ", "            A A            ", "            A A            ", "             A             ", "                           ")
                    .aisle("     HLLLLLLLLLLLLLLLH     ", "     HL             LH     ", "     HHH           HHH     ", "      HH           HH      ", "      HH           HH      ", "      LLH         HLL      ", "       LH         HL       ", "       LH         HL       ", "       LL         LL       ", "        L         L        ", "       LL         LL       ", "       LHLHLLHLLHLHL       ", "       L L       L L       ", "         L       L         ", "         LH     HL         ", "         MH     HM         ", "         MH     HM         ", "         MH     HM         ", "         L       L         ", "        LL       LL        ", "        LL       LL        ", "        LL       LL        ", "        MJFFFFFFFJM        ", "        EJ       JE        ", "        EJ       JE        ", "        EJ       JE        ", "        EJ       JE        ", "        EJ       JE        ", "        FJ       JF        ", "        FJ       JF        ", "        FJ       JF        ", "        FJ       JF        ", "        FJ       JF        ", "       FFJ       JFF       ", "       FFJ       JFF       ", "      FFFJ       JFFF      ", "    DFFFFJFFFFFFFJFFFFD    ", "    EJFJFJ       JFJFJE    ", "    EJKJKJ       JKJKJE    ", "    EJFJFJ       JFJFJE    ", "    EJ J J       J J JE    ", "    FJ J J       J J JF    ", "   AAJ J J       J J JAA   ", "  AAAAAAAAF     FAAAAAAAA  ", "  AAAAAAAAF     FAAAAAAAA  ", "          F     F          ", "          F     F          ", "          F     F          ", "          F     F          ", "       DDDFFFFFFFDDD       ", "       EJ         JE       ", "       EJ         JE       ", "       EJ         JE       ", "      AFJ         JFA      ", "     AAAAAAA   AAAAAAA     ", "     AAAAAAA   AAAAAAA     ", "            A A            ", "            A A            ", "            A A            ", "             A             ", "                           ")
                    .aisle("     HLLLLLLLLLLLLLLLH     ", "     IL             LI     ", "      H             H      ", "       H           H       ", "      H             H      ", "       IH         HI       ", "        H         H        ", "        H         H        ", "        H         H        ", "        H         H        ", "        H         H        ", "      LHHLHLLHLLHLHHL      ", "      L ML       LM L      ", "        ML       LM        ", "        NHH     HHN        ", "          R     R          ", "          R     R          ", "          R     R          ", "          H     H          ", "         LH     HL         ", "        LL       LL        ", "        LL       LL        ", "         LFFFFFFFL         ", "        OGF     FGO        ", "          F     F          ", "         EF     FE         ", "         EF     FE         ", "         EF     FE         ", "         EF     FE         ", "         EF     FE         ", "        FF       FF        ", "        F         F        ", "        PF       FP        ", "        DF       FD        ", "         E       E         ", "         E       E         ", "    DFFFFFFFFFFFFFFFFFD    ", "    EK               KE    ", "     K               K     ", "     K               K     ", "     K               K     ", "    DK               KD    ", "   CGF               FGC   ", "     F    F     F    F     ", "  AAAF    F     F    FAAA  ", "  AAAAAAAAF     FAAAAAAAA  ", " AAAAAAAAAF     FAAAAAAAAA ", " AAAAAAAAAF     FAAAAAAAAA ", "          F     F          ", "       DDDFFFFFFFDDD       ", "       EK         KE       ", "        K         K        ", "        K         K        ", "       DK         KD       ", "      CGF         FGC      ", "     A  F         F  A     ", "     AAAAAAAA AAAAAAAA     ", "    AAAAAAAAA AAAAAAAAA    ", "    AAAAAAAAA AAAAAAAAA    ", "             A             ", "                           ")
                    .aisle("     HLLLLLLLLLLLLLLLH     ", "     HL      T      LH     ", "     HHH           HHH     ", "      HH           HH      ", "      HH           HH      ", "      LLH         HLL      ", "       LH         HL       ", "       LH         HL       ", "       LL         LL       ", "        L         L        ", "       LL         LL       ", "      IHHHHHHHHHHHHHI      ", "         Q   T   Q         ", "         Q       Q         ", "        NLH     HLN        ", "         MH     HM         ", "         MH     HM         ", "         MH     HM         ", "         MH     HM         ", "         MH     HM         ", "         L       L         ", "       LLL       LLL       ", "     ILLLLFFFFFFFLLLLI     ", "        OGF  T  FGO        ", "          K     K          ", "          K     K          ", "          K     K          ", "          F     F          ", "          K     K          ", "         CF     FC         ", "        CB       BC        ", "       FF         FF       ", "      DDFF       FFDD      ", "       FFF       FFF       ", "       FFF       FFF       ", "      FFFF       FFFF      ", "    DFFFFFFFFFFFFFFFFFD    ", "    EK       T       KE    ", "     K               K     ", "     K               K     ", "     K               K     ", "    DK               KD    ", "   CGF               FGC   ", "     F    F     F    F     ", "     K    F     F    K     ", "    CF    F     F    FC    ", "   CB     F     F     BC   ", " AAAAAAAAAF     FAAAAAAAAA ", "AAAAAAAAAAF     FAAAAAAAAAA", "A      DDDFFFFFFFDDD      A", "       EK    T    KE       ", "        K         K        ", "        K         K        ", "       DK         KD       ", "      CGF         FGC      ", "        F         F        ", "        K         K        ", "       CJ         JC       ", "    A CB           BC A    ", "   AAAAAAAAAAJAAAAAAAAAA   ", "   A                   A   ")
                    .aisle("     HLLLLLLLLLLLLLLLH     ", "     IL             LI     ", "      H             H      ", "       H           H       ", "      H             H      ", "       IH         HI       ", "        H         H        ", "        H         H        ", "        H         H        ", "        H         H        ", "        H         H        ", "      LHHLHLLHLLHLHHL      ", "      L ML       LM L      ", "        ML       LM        ", "        NHH     HHN        ", "          R     R          ", "          R     R          ", "          R     R          ", "          H     H          ", "         LH     HL         ", "        LL       LL        ", "        LL       LL        ", "         LFFFFFFFL         ", "        OGF     FGO        ", "          F     F          ", "         EF     FE         ", "         EF     FE         ", "         EF     FE         ", "         EF     FE         ", "         EF     FE         ", "        FF       FF        ", "        F         F        ", "        PF       FP        ", "        DF       FD        ", "         E       E         ", "         E       E         ", "    DFFFFFFFFFFFFFFFFFD    ", "    EK               KE    ", "     K               K     ", "     K               K     ", "     K               K     ", "    DK               KD    ", "   CGF               FGC   ", "     F    F     F    F     ", "  AAAF    F     F    FAAA  ", "  AAAAAAAAF     FAAAAAAAA  ", " AAAAAAAAAF     FAAAAAAAAA ", " AAAAAAAAAF     FAAAAAAAAA ", "          F     F          ", "       DDDFFFFFFFDDD       ", "       EK         KE       ", "        K         K        ", "        K         K        ", "       DK         KD       ", "      CGF         FGC      ", "     A  F         F  A     ", "     AAAAAAAA AAAAAAAA     ", "    AAAAAAAAA AAAAAAAAA    ", "    AAAAAAAAA AAAAAAAAA    ", "             A             ", "                           ")
                    .aisle("     HLLLLLLLLLLLLLLLH     ", "     HL             LH     ", "     HHH           HHH     ", "      HH           HH      ", "      HH           HH      ", "      LLH         HLL      ", "       LH         HL       ", "       LH         HL       ", "       LL         LL       ", "        L         L        ", "       LL         LL       ", "       LHLHLLHLLHLHL       ", "       L L       L L       ", "         L       L         ", "         LH     HL         ", "         MH     HM         ", "         MH     HM         ", "         MH     HM         ", "         L       L         ", "        LL       LL        ", "        LL       LL        ", "        LL       LL        ", "        MJFFFFFFFJM        ", "        EJ       JE        ", "        EJ       JE        ", "        EJ       JE        ", "        EJ       JE        ", "        EJ       JE        ", "        FJ       JF        ", "        FJ       JF        ", "        FJ       JF        ", "        FJ       JF        ", "        FJ       JF        ", "       FFJ       JFF       ", "       FFJ       JFF       ", "      FFFJ       JFFF      ", "    DFFFFJFFFFFFFJFFFFD    ", "    EJFJFJ       JFJFJE    ", "    EJKJKJ       JKJKJE    ", "    EJFJFJ       JFJFJE    ", "    EJ J J       J J JE    ", "    FJ J J       J J JF    ", "   AAJ J J       J J JAA   ", "  AAAAAAAAF     FAAAAAAAA  ", "  AAAAAAAAF     FAAAAAAAA  ", "          F     F          ", "          F     F          ", "          F     F          ", "          F     F          ", "       DDDFFFFFFFDDD       ", "       EJ         JE       ", "       EJ         JE       ", "       EJ         JE       ", "      AFJ         JFA      ", "     AAAAAAA   AAAAAAA     ", "     AAAAAAA   AAAAAAA     ", "            A A            ", "            A A            ", "            A A            ", "             A             ", "                           ")
                    .aisle("      HLLLLLLLLLLLLLH      ", "      IL           LI      ", "       H           H       ", "        H         H        ", "       H           H       ", "       IH         HI       ", "        H         H        ", "        H         H        ", "        H         H        ", "        H         H        ", "        H         H        ", "        HLHHHHHHHLH        ", "        HL       LH        ", "        ML       LM        ", "        ML HHHHH LM        ", "        ML HRHRH LM        ", "        ML HRHRH LM        ", "        ML HRHRH LM        ", "        ML  HHH  LM        ", "        LL  HHH  LL        ", "         L       L         ", "         LL     LL         ", "         MJFFFFFJM         ", "         EJ FFF JE         ", "         EJ FKF JE         ", "         EJ FKF JE         ", "        FFJ FKF JFF        ", "        FFJ FFF JFF        ", "        FFJ FKF JFF        ", "         EJ FFF JE         ", "         EJ     JE         ", "         EJ     JE         ", "         EJ     JE         ", "         EJ     JE         ", "         EJ     JE         ", "         EJ     JE         ", "         EJFFFFFJE         ", "         EJ     JE         ", "         EJ     JE         ", "    AAAAAAJ     JAAAAAA    ", "   AAAAAAAJ     JAAAAAAA   ", "   AAAAAAAJ     JAAAAAAA   ", "   AAAAAAAJ     JAAAAAAA   ", "          JFFFFFJ          ", "          JFFFFFJ          ", "          JFFFFFJ          ", "         FJFFFFFJF         ", "         FJFFFFFJF         ", "        FFJFFFFFJFF        ", "       FFFJFFFFFJFFF       ", "       AAAA     AAAA       ", "       AAAA     AAAA       ", "      AAAAA     AAAAA      ", "      AAAAA     AAAAA      ", "           A   A           ", "           A   A           ", "            A A            ", "            A A            ", "            A A            ", "             A             ", "                           ")
                    .aisle("      HLLLLLLLLLLLLLH      ", "      HL           LH      ", "      HHH         HHH      ", "       HH         HH       ", "       HH         HH       ", "       LLH       HLL       ", "        LH       HL        ", "        LH       HL        ", "        LL       LL        ", "         L       L         ", "         L       L         ", "          LLLHLLL          ", "          LLLQLLL          ", "          LLLQLLL          ", "          LLHLHLL          ", "          LM M ML          ", "          LM M ML          ", "          LM M ML          ", "          LL M LL          ", "          LLLMLLL          ", "          LLLLLLL          ", "          LLLLLLL          ", "          MJLLLJM          ", "          EJGGGJE          ", "          EJ   JE          ", "          EJE EJE          ", "          FJE EJF          ", "          FJE EJF          ", "          FJE EJF          ", "          EJECEJE          ", "          EJFBFJE          ", "          EJ   JE          ", "          EJFFFJE          ", "          EJFFFJE          ", "          EJEFEJE          ", "          EJEFEJE          ", "          EJFFFJE          ", "          EJ   JE          ", "          EJ   JE          ", "    AAAAAAAJ   JAAAAAAA    ", "    AAAAAAAJ   JAAAAAAA    ", "          AJ   JA          ", "          AJ   JA          ", "           A   A           ", "           A   A           ", "            A A            ", "          F A A F          ", "          F AAA F          ", "          F  A  F          ", "          FDDDDDF          ", "       AAAA     AAAA       ", "          A     A          ", "          A     A          ", "          A     A          ", "           A   A           ", "           A   A           ", "            A A            ", "            A A            ", "            A A            ", "             A             ", "                           ")
                    .aisle("       HLLLLLLLLLLLH       ", "       HL         LH       ", "       HHH       HHH       ", "        HHH     HHH        ", "        HH       HH        ", "        ILHHHHHHHLI        ", "         LHHHHHHHL         ", "         LHHHHHHHL         ", "         LHLHLHLHL         ", "          HLHLHLH          ", "          HLHLHLH          ", "          HHHHHHH          ", "          H M M H          ", "          M M M M          ", "          M NNN M          ", "          M     M          ", "          M     M          ", "          M     M          ", "          M     M          ", "          LL   LL          ", "           LL LL           ", "           LLLLL           ", "           M L M           ", "           EOOOE           ", "           E   E           ", "           E   E           ", "          FE   EF          ", "          FE   EF          ", "          FF   FF          ", "           F   F           ", "           FFCFF           ", "           FFFFF           ", "           FPFPF           ", "           FDFDF           ", "           F F F           ", "           F F F           ", "           FFFFF           ", "           F   F           ", "           K   K           ", "         AAF   FAA         ", "         AA     AA         ", "          A     A          ", "          A     A          ", "           A   A           ", "           A   A           ", "            A A            ", "            A A            ", "            AAA            ", "          F  A  F          ", "          FDDDDDF          ", "         AAJKKKJAA         ", "          AJKKKJA          ", "          AJKKKJA          ", "          AJKKKJA          ", "           AFFFA           ", "           AFFFA           ", "            AKA            ", "            AJA            ", "            A A            ", "             A             ", "                           ")
                    .aisle("        HLLHLLLHLLH        ", "        HLLH   HLLH        ", "        HHHH   HHHH        ", "         H H   H H         ", "         HHHHHHHHH         ", "         LILILILIL         ", "           L L L           ", "           L L L           ", "           L L L           ", "                           ", "           L L L           ", "           LHHHL           ", "           L   L           ", "                           ", "                           ", "                           ", "                           ", "                           ", "                           ", "                           ", "                           ", "             L             ", "             L             ", "                           ", "                           ", "                           ", "                           ", "                           ", "                           ", "                           ", "                           ", "             F             ", "             D             ", "           F F F           ", "           F F F           ", "           F F F           ", "           FFFFF           ", "           J   J           ", "           J   J           ", "         AAJ   JAA         ", "         AAJ   JAA         ", "          AJ   JA          ", "          AJ   JA          ", "           A   A           ", "           A   A           ", "            A A            ", "            A A            ", "            AAA            ", "             A             ", "          FDDDDDF          ", "         AAEEEEEAA         ", "          AE   EA          ", "          AE   EA          ", "          AFDDDFA          ", "           AGGGA           ", "           A   A           ", "            A A            ", "            ACA            ", "            ABA            ", "             A             ", "                           ")
                    .aisle("         HHHS~SHHH         ", "         HIH   HIH         ", "         H H   H H         ", "           H   H           ", "           HHHHH           ", "           L L L           ", "                           ", "                           ", "                           ", "                           ", "                           ", "            LIL            ", "            L L            ", "                           ", "                           ", "                           ", "                           ", "                           ", "                           ", "                           ", "                           ", "                           ", "             L             ", "                           ", "                           ", "                           ", "                           ", "                           ", "                           ", "                           ", "                           ", "                           ", "             D             ", "                           ", "                           ", "           F F F           ", "           FFFFF           ", "           F   F           ", "           K   K           ", "         AAF   FAA         ", "         AA     AA         ", "          A     A          ", "          A     A          ", "           A   A           ", "           A   A           ", "            A A            ", "            A A            ", "            AAA            ", "             A             ", "                           ", "                           ", "                           ", "          A     A          ", "          AA   AA          ", "           ACCCA           ", "           A   A           ", "            A A            ", "            A A            ", "            ACA            ", "             A             ", "                           ")
                    .aisle("           H   H           ", "           H   H           ", "           H   H           ", "                           ", "                           ", "                           ", "                           ", "                           ", "                           ", "                           ", "                           ", "                           ", "                           ", "                           ", "                           ", "                           ", "                           ", "                           ", "                           ", "                           ", "                           ", "                           ", "             I             ", "                           ", "                           ", "                           ", "                           ", "                           ", "                           ", "                           ", "                           ", "                           ", "                           ", "                           ", "                           ", "                           ", "           FFFFF           ", "           JKKKJ           ", "           JKKKJ           ", "         AAJKKKJAA         ", "         AAJKKKJAA         ", "          AJKKKJA          ", "          AJFFFJA          ", "           AFFFA           ", "           AFKFA           ", "            AFA            ", "            A A            ", "            AAA            ", "             A             ", "                           ", "                           ", "                           ", "                           ", "                           ", "           A   A           ", "           AA AA           ", "            A A            ", "            A A            ", "            A A            ", "             A             ", "                           ")
                    .aisle("                           ", "                           ", "                           ", "                           ", "                           ", "                           ", "                           ", "                           ", "                           ", "                           ", "                           ", "                           ", "                           ", "                           ", "                           ", "                           ", "                           ", "                           ", "                           ", "                           ", "                           ", "                           ", "                           ", "                           ", "                           ", "                           ", "                           ", "                           ", "                           ", "                           ", "                           ", "                           ", "                           ", "                           ", "                           ", "                           ", "           DDDDD           ", "           EEEEE           ", "           E   E           ", "         AAE   EAA         ", "         AAE   EAA         ", "          AFDDDFA          ", "          AAGGGAA          ", "           A   A           ", "           AA AA           ", "            ACA            ", "            ABA            ", "            AAA            ", "             A             ", "                           ", "                           ", "                           ", "                           ", "                           ", "                           ", "                           ", "                           ", "            A A            ", "            AAA            ", "             A             ", "                           ")
                    .aisle("                           ", "                           ", "                           ", "                           ", "                           ", "                           ", "                           ", "                           ", "                           ", "                           ", "                           ", "                           ", "                           ", "                           ", "                           ", "                           ", "                           ", "                           ", "                           ", "                           ", "                           ", "                           ", "                           ", "                           ", "                           ", "                           ", "                           ", "                           ", "                           ", "                           ", "                           ", "                           ", "                           ", "                           ", "                           ", "                           ", "                           ", "                           ", "                           ", "                           ", "          A     A          ", "          A     A          ", "          AACCCAA          ", "           A   A           ", "           AA AA           ", "            A A            ", "            ACA            ", "            AAA            ", "             A             ", "                           ", "                           ", "                           ", "                           ", "                           ", "                           ", "                           ", "                           ", "                           ", "                           ", "             A             ", "             A             ")
                    .aisle("                           ", "                           ", "                           ", "                           ", "                           ", "                           ", "                           ", "                           ", "                           ", "                           ", "                           ", "                           ", "                           ", "                           ", "                           ", "                           ", "                           ", "                           ", "                           ", "                           ", "                           ", "                           ", "                           ", "                           ", "                           ", "                           ", "                           ", "                           ", "                           ", "                           ", "                           ", "                           ", "                           ", "                           ", "                           ", "                           ", "                           ", "                           ", "                           ", "                           ", "                           ", "                           ", "                           ", "           A   A           ", "           AA AA           ", "            A A            ", "            A A            ", "            AAA            ", "             A             ", "                           ", "                           ", "                           ", "                           ", "                           ", "                           ", "                           ", "                           ", "                           ", "                           ", "                           ", "                           ")
                    .aisle("                           ", "                           ", "                           ", "                           ", "                           ", "                           ", "                           ", "                           ", "                           ", "                           ", "                           ", "                           ", "                           ", "                           ", "                           ", "                           ", "                           ", "                           ", "                           ", "                           ", "                           ", "                           ", "                           ", "                           ", "                           ", "                           ", "                           ", "                           ", "                           ", "                           ", "                           ", "                           ", "                           ", "                           ", "                           ", "                           ", "                           ", "                           ", "                           ", "                           ", "                           ", "                           ", "                           ", "                           ", "                           ", "                           ", "            A A            ", "            AAA            ", "             A             ", "                           ", "                           ", "                           ", "                           ", "                           ", "                           ", "                           ", "                           ", "                           ", "                           ", "                           ", "                           ")
                    .aisle("                           ", "                           ", "                           ", "                           ", "                           ", "                           ", "                           ", "                           ", "                           ", "                           ", "                           ", "                           ", "                           ", "                           ", "                           ", "                           ", "                           ", "                           ", "                           ", "                           ", "                           ", "                           ", "                           ", "                           ", "                           ", "                           ", "                           ", "                           ", "                           ", "                           ", "                           ", "                           ", "                           ", "                           ", "                           ", "                           ", "                           ", "                           ", "                           ", "                           ", "                           ", "                           ", "                           ", "                           ", "                           ", "                           ", "                           ", "                           ", "             A             ", "             A             ", "                           ", "                           ", "                           ", "                           ", "                           ", "                           ", "                           ", "                           ", "                           ", "                           ", "                           ")
                    .where("~", Predicates.controller(Predicates.blocks(definition.get())))
                    .where("I", Predicates.blocks(Registries.getBlock("minecraft:stone_brick_slab")))
                    .where("O", Predicates.blocks(Registries.getBlock("minecraft:spruce_fence_gate")))
                    .where("P", Predicates.blocks(Registries.getBlock("minecraft:spruce_button")))
                    .where("S", Predicates.blocks(Registries.getBlock("gtceu:magic_hazard_sign_block")))
                    .where("R", Predicates.blocks(Registries.getBlock("minecraft:iron_bars")))
                    .where("D", Predicates.blocks(Registries.getBlock("minecraft:spruce_slab")))
                    .where("B", Predicates.blocks(Registries.getBlock("minecraft:sea_lantern")))
                    .where("T", Predicates.blocks(Registries.getBlock("gtceu:uhv_ultimate_battery")))
                    .where("A", Predicates.blocks(Registries.getBlock("minecraft:oak_planks")))
                    .where("K", Predicates.blocks(Registries.getBlock("minecraft:brown_stained_glass_pane")))
                    .where("C", Predicates.blocks(Registries.getBlock("minecraft:oak_trapdoor")))
                    .where("N", Predicates.blocks(Registries.getBlock("minecraft:cobblestone_slab")))
                    .where("G", Predicates.blocks(Registries.getBlock("minecraft:grass_block")))
                    .where("L", Predicates.blocks(Registries.getBlock("minecraft:stone_bricks")))
                    .where("E", Predicates.blocks(Registries.getBlock("minecraft:spruce_fence")))
                    .where("H", Predicates.blocks(Registries.getBlock("minecraft:cobblestone")))
                    .where("J", Predicates.blocks(Registries.getBlock("minecraft:oak_log")))
                    .where("M", Predicates.blocks(Registries.getBlock("minecraft:cobblestone_wall")))
                    .where("Q", Predicates.blocks(Registries.getBlock("minecraft:spruce_door")))
                    .where("F", Predicates.blocks(Registries.getBlock("minecraft:spruce_planks")))
                    .build())
            .workableCasingRenderer(GTCEu.id("block/casings/signs/machine_casing_magichazard"), GTCEu.id("block/multiblock/vacuum_freezer"))
            .register();

    /// *奥术集成装置*
    public final static MultiblockMachineDefinition ARCANE_INTEGRATED_DEVICE = REGISTRATE.multiblock("arcane_integrated_device", WorkableElectricMultiblockMachine::new)
            .rotationState(RotationState.NON_Y_AXIS)
            .allowExtendedFacing(false)
            .recipeType(GTLRecipeTypes.INFUSION_RITUAL)
            .tooltips(Component.translatable("gtlcore.machine.arcane_integrated_device.tooltip.1"))
            .pattern(definition -> FactoryBlockPattern.start()
                    .aisle(ArcaneIntegratedDeviceA.A_1)
                    .aisle(ArcaneIntegratedDeviceA.A_2)
                    .aisle(ArcaneIntegratedDeviceA.A_3)
                    .aisle(ArcaneIntegratedDeviceA.A_4)
                    .aisle(ArcaneIntegratedDeviceA.A_5)
                    .aisle(ArcaneIntegratedDeviceA.A_6)
                    .aisle(ArcaneIntegratedDeviceA.A_7)
                    .aisle(ArcaneIntegratedDeviceA.A_8)
                    .aisle(ArcaneIntegratedDeviceA.A_9)
                    .aisle(ArcaneIntegratedDeviceA.A_10)
                    .aisle(ArcaneIntegratedDeviceA.A_11)
                    .aisle(ArcaneIntegratedDeviceA.A_12)
                    .aisle(ArcaneIntegratedDeviceA.A_13)
                    .aisle(ArcaneIntegratedDeviceA.A_14)
                    .aisle(ArcaneIntegratedDeviceA.A_15)
                    .aisle(ArcaneIntegratedDeviceA.A_16)
                    .aisle(ArcaneIntegratedDeviceA.A_17)
                    .aisle(ArcaneIntegratedDeviceA.A_18)
                    .aisle(ArcaneIntegratedDeviceA.A_19)
                    .aisle(ArcaneIntegratedDeviceA.A_20)
                    .aisle(ArcaneIntegratedDeviceA.A_21)
                    .aisle(ArcaneIntegratedDeviceA.A_22)
                    .aisle(ArcaneIntegratedDeviceA.A_23)
                    .aisle(ArcaneIntegratedDeviceA.A_24)
                    .aisle(ArcaneIntegratedDeviceA.A_25)
                    .aisle(ArcaneIntegratedDeviceA.A_26)
                    .aisle(ArcaneIntegratedDeviceA.A_27)
                    .aisle(ArcaneIntegratedDeviceA.A_28)
                    .aisle(ArcaneIntegratedDeviceA.A_29)
                    .aisle(ArcaneIntegratedDeviceA.A_30)
                    .aisle(ArcaneIntegratedDeviceA.A_31)
                    .aisle(ArcaneIntegratedDeviceA.A_32)
                    .aisle(ArcaneIntegratedDeviceA.A_33)
                    .aisle(ArcaneIntegratedDeviceA.A_34)
                    .aisle(ArcaneIntegratedDeviceA.A_35)
                    .aisle(ArcaneIntegratedDeviceA.A_36)
                    .aisle(ArcaneIntegratedDeviceA.A_37)
                    .aisle(ArcaneIntegratedDeviceA.A_38)
                    .aisle(ArcaneIntegratedDeviceA.A_39)
                    .aisle(ArcaneIntegratedDeviceA.A_40)
                    .aisle(ArcaneIntegratedDeviceA.A_41)
                    .aisle(ArcaneIntegratedDeviceA.A_42)
                    .aisle(ArcaneIntegratedDeviceA.A_43)
                    .aisle(ArcaneIntegratedDeviceA.A_44)
                    .aisle(ArcaneIntegratedDeviceA.A_45)
                    .aisle(ArcaneIntegratedDeviceA.A_46)
                    .aisle(ArcaneIntegratedDeviceB.A_47)
                    .aisle(ArcaneIntegratedDeviceB.A_48)
                    .aisle(ArcaneIntegratedDeviceB.A_49)
                    .aisle(ArcaneIntegratedDeviceB.A_50)
                    .aisle(ArcaneIntegratedDeviceB.A_51)
                    .aisle(ArcaneIntegratedDeviceB.A_52)
                    .aisle(ArcaneIntegratedDeviceB.A_53)
                    .aisle(ArcaneIntegratedDeviceB.A_54)
                    .aisle(ArcaneIntegratedDeviceB.A_55)
                    .aisle(ArcaneIntegratedDeviceB.A_56)
                    .aisle(ArcaneIntegratedDeviceB.A_57)
                    .aisle(ArcaneIntegratedDeviceB.A_58)
                    .aisle(ArcaneIntegratedDeviceB.A_59)
                    .aisle(ArcaneIntegratedDeviceB.A_60)
                    .aisle(ArcaneIntegratedDeviceB.A_61)
                    .aisle(ArcaneIntegratedDeviceB.A_62)
                    .aisle(ArcaneIntegratedDeviceB.A_63)
                    .aisle(ArcaneIntegratedDeviceB.A_64)
                    .aisle(ArcaneIntegratedDeviceB.A_65)
                    .aisle(ArcaneIntegratedDeviceB.A_66)
                    .aisle(ArcaneIntegratedDeviceB.A_67)
                    .aisle(ArcaneIntegratedDeviceB.A_68)
                    .aisle(ArcaneIntegratedDeviceB.A_69)
                    .aisle(ArcaneIntegratedDeviceB.A_70)
                    .aisle(ArcaneIntegratedDeviceB.A_71)
                    .aisle(ArcaneIntegratedDeviceB.A_72)
                    .aisle(ArcaneIntegratedDeviceB.A_73)
                    .aisle(ArcaneIntegratedDeviceB.A_74)
                    .aisle(ArcaneIntegratedDeviceB.A_75)
                    .aisle(ArcaneIntegratedDeviceB.A_76)
                    .aisle(ArcaneIntegratedDeviceB.A_77)
                    .aisle(ArcaneIntegratedDeviceB.A_78)
                    .aisle(ArcaneIntegratedDeviceB.A_79)
                    .aisle(ArcaneIntegratedDeviceB.A_80)
                    .aisle(ArcaneIntegratedDeviceB.A_81)
                    .aisle(ArcaneIntegratedDeviceB.A_82)
                    .aisle(ArcaneIntegratedDeviceB.A_83)
                    .aisle(ArcaneIntegratedDeviceB.A_84)
                    .aisle(ArcaneIntegratedDeviceB.A_85)
                    .aisle(ArcaneIntegratedDeviceB.A_86)
                    .aisle(ArcaneIntegratedDeviceB.A_87)
                    .aisle(ArcaneIntegratedDeviceB.A_88)
                    .aisle(ArcaneIntegratedDeviceB.A_89)
                    .aisle(ArcaneIntegratedDeviceB.A_90)
                    .aisle(ArcaneIntegratedDeviceB.A_91)
                    .where("E", Predicates.blocks(GTLBlocks.ECHO_CASING.get()))
                    .where("H", Predicates.blocks(Registries.getBlock("minecraft:bedrock")))
                    .where("B", Predicates.blocks(Registries.getBlock("minecraft:obsidian")))
                    .where("I", Predicates.blocks(Registries.getBlock("minecraft:end_gateway")))
                    .where("J", Predicates.controller(Predicates.blocks(definition.get())))
                    .where("D", Predicates.blocks(Registries.getBlock("minecraft:beacon")))
                    .where("G", Predicates.blocks(Registries.getBlock("gtlcore:quantum_glass")))
                    .where("F", Predicates.blocks(GTLBlocks.OMNI_PURPOSE_INFINITY_FUSED_GLASS.get()))
                    .where("C", Predicates.blocks(Registries.getBlock("gtlcore:chemical_grade_glass")))
                    .where("A", Predicates.blocks(Registries.getBlock("minecraft:quartz_block")))
                    .build())
            .multiblockPreviewRenderer(true, false)
            .workableCasingRenderer(GTCEu.id("block/casings/signs/machine_casing_magichazard"), GTCEu.id("block/multiblock/vacuum_freezer"))
            .register();
}
